{"uuid": "d72bb522-be9a-434f-a560-e9ef31f13212", "children": ["fa3ba3c9-87b4-4588-96ae-bff5c7caf1f7", "daf83ead-bfdb-4429-98ae-d8a281577516", "c74d2526-3a8d-464f-926d-a299a350005b", "e1b2a0b9-3f00-4bf3-b692-00836440e016", "ae8a06a9-5db5-4bd0-b7e3-8f2f51d0de39", "ad8ee269-c297-46a6-b1fb-7c5d584ffd69", "c660b76c-645f-48a3-9df5-4bb81b099f70", "733fc886-43ae-43e0-9665-04345626be4f", "aef44257-b5b1-4dc2-8cea-f3ee2dd0bfa2", "6738e27d-55c7-453d-9daf-39d2d558d601", "e2a3a1de-6e02-448d-8a71-c7de76a2e62d", "5867b36f-d085-4011-98b1-397fac8f5a3d", "f1a4eb2d-0c13-47b3-bc34-1158c56e7b24", "40190883-01ef-4c78-b0ef-fb8f7af2ca50", "9c8356b8-681b-486e-9a2c-b2b108824f6b", "87e8cd15-3f15-4a25-9c6b-93cf1bbee743"], "befores": [{"name": "driver", "status": "passed", "start": 1714464085893, "stop": 1714464094430}], "afters": [{"name": "driver::0", "status": "broken", "statusDetails": {"message": "selenium.common.exceptions.InvalidSessionIdException: Message: invalid session id\nStacktrace:\n\tGetHandleVerifier [0x00007FF6CFD778A2+54818]\n\t(No symbol) [0x00007FF6CFCE6AD2]\n\t(No symbol) [0x00007FF6CFB9D8ED]\n\t(No symbol) [0x00007FF6CFBD30DE]\n\t(No symbol) [0x00007FF6CFBFE9A2]\n\t(No symbol) [0x00007FF6CFBFA710]\n\t(No symbol) [0x00007FF6CFBFA016]\n\t(No symbol) [0x00007FF6CFB741D0]\n\tGetHandleVerifier [0x00007FF6D00DB9A2+3610402]\n\tGetHandleVerifier [0x00007FF6D0131870+3962352]\n\tGetHandleVerifier [0x00007FF6D0129D5F+3930847]\n\tGetHandleVerifier [0x00007FF6CFE13656+693206]\n\t(No symbol) [0x00007FF6CFCF1638]\n\t(No symbol) [0x00007FF6CFB72FFE]\n\tGetHandleVerifier [0x00007FF6D0172288+4227080]\n\tBaseThreadInitThunk [0x00007FFEE159257D+29]\n\tRtlUserThreadStart [0x00007FFEE202AA58+40]\n\n", "trace": "  File \"D:\\sw_install\\python-install\\lib\\site-packages\\allure_commons\\_allure.py\", line 221, in __call__\n    return self._fixture_function(*args, **kwargs)\n  File \"D:\\sw_install\\python-install\\lib\\site-packages\\_pytest\\fixtures.py\", line 918, in _teardown_yield_fixture\n    next(it)\n  File \"D:\\ui\\conftest.py\", line 37, in driver\n    driver.close()\n  File \"D:\\sw_install\\python-install\\lib\\site-packages\\selenium\\webdriver\\remote\\webdriver.py\", line 459, in close\n    self.execute(Command.CLOSE)\n  File \"D:\\sw_install\\python-install\\lib\\site-packages\\selenium\\webdriver\\remote\\webdriver.py\", line 348, in execute\n    self.error_handler.check_response(response)\n  File \"D:\\sw_install\\python-install\\lib\\site-packages\\selenium\\webdriver\\remote\\errorhandler.py\", line 229, in check_response\n    raise exception_class(message, screen, stacktrace)\n"}, "start": 1714465610544, "stop": 1714465610812}], "start": 1714464085893, "stop": 1714465610812}