{"uuid": "eb659a59-29ad-47a7-8401-866df0404dfb", "children": ["cb9cb0ae-7480-46dc-89d6-6f41901e9140", "1e2f35d7-9109-42d1-9ec3-6c41e297a18e", "138872d6-7ef9-4024-904f-16b5059de35d", "197a68e1-ac1d-411c-a138-ad212ede34ca", "e8a1fb32-4a41-4f92-84a7-2af2613f00c7", "4c51e593-d440-40f5-91b3-8f2600fa3079", "1042c915-0c98-4174-bf89-d7b77802e549", "a8fff400-bbbf-4b52-9fbd-4e22b4460e71", "b045ac4e-a4ff-4e26-90a3-a804af591e85", "15eda28e-e750-4f14-8e59-e63879451672", "317a652c-c827-4924-8988-4003d25e03c4", "ccb69ef9-bb50-4079-903b-34e8f099e591", "1480c30a-74c5-433a-903e-8f8b9d97af67", "ceb05526-b581-4b8b-9d58-de24bd1473db", "29f69b3e-679d-4f46-bde2-17686033c9d4", "bc80b3c6-9fcc-48f5-b335-b584072a4d3b"], "befores": [{"name": "driver", "status": "passed", "start": 1714992107181, "stop": 1714992118272}], "afters": [{"name": "driver::0", "status": "broken", "statusDetails": {"message": "pymysql.err.OperationalError: (2003, \"Can't connect to MySQL server on 'rm-wz9vq722u8axcvo06oo.mysql.rds.aliyuncs.com' ([Errno 11001] getaddrinfo failed)\")\n", "trace": "  File \"D:\\sw_install\\python-install\\lib\\site-packages\\allure_commons\\_allure.py\", line 221, in __call__\n    return self._fixture_function(*args, **kwargs)\n  File \"D:\\sw_install\\python-install\\lib\\site-packages\\_pytest\\fixtures.py\", line 918, in _teardown_yield_fixture\n    next(it)\n  File \"D:\\ui\\conftest.py\", line 36, in driver\n    sql_execute()\n  File \"D:\\ui\\data_clean.py\", line 8, in sql_execute\n    connection = pymysql.connect(host=host, port=3391, user='hkc_cv_user', password='Hkc285$$', database='hkc_cv')\n  File \"D:\\sw_install\\python-install\\lib\\site-packages\\pymysql\\connections.py\", line 358, in __init__\n    self.connect()\n  File \"D:\\sw_install\\python-install\\lib\\site-packages\\pymysql\\connections.py\", line 711, in connect\n    raise exc\n"}, "start": 1714992971930, "stop": 1714992971930}], "start": 1714992107181, "stop": 1714992971930}