{"uuid": "5ed5f230-4de5-4aff-aea9-d29997bd735d", "children": ["6bc48de0-0482-4959-b445-cb45b84d31ab", "f876d3e6-4cd8-4ab5-8406-418087663a6d", "0544e204-cdeb-4bd4-a2eb-fde0a6ed918d", "80774e11-5eec-4224-9f5c-99893ee3d726", "0d037d50-798e-49c2-bc75-993e28063432", "02053217-eed3-4ded-900d-10aa94cca64f", "2022c08a-8427-4916-b986-da158ad5b54c", "4e731edc-6da5-4126-b4ad-b597dac9aa91", "286d2dcd-8456-468c-b5b9-7a92a7595237"], "befores": [{"name": "driver", "status": "passed", "start": 1716618657891, "stop": 1716618664177}], "afters": [{"name": "driver::0", "status": "broken", "statusDetails": {"message": "OSError: [Errno 22] Invalid argument\n", "trace": "  File \"D:\\sw_install\\python-install\\lib\\site-packages\\allure_commons\\_allure.py\", line 221, in __call__\n    return self._fixture_function(*args, **kwargs)\n  File \"D:\\sw_install\\python-install\\lib\\site-packages\\_pytest\\fixtures.py\", line 918, in _teardown_yield_fixture\n    next(it)\n  File \"D:\\ui\\conftest.py\", line 36, in driver\n    api_clear_data()\n  File \"D:\\ui\\data_clean.py\", line 91, in api_clear_data\n    traceback.print_exc()\n  File \"D:\\sw_install\\python-install\\lib\\traceback.py\", line 179, in print_exc\n    print_exception(*sys.exc_info(), limit=limit, file=file, chain=chain)\n  File \"D:\\sw_install\\python-install\\lib\\traceback.py\", line 121, in print_exception\n    print(line, file=file, end=\"\")\n"}, "start": 1716633923435, "stop": 1716633923509}], "start": 1716618657891, "stop": 1716633923509}