{"uuid": "d3f8f7b5-2970-42ab-9231-ad593c004ce9", "children": ["7c16028b-0ef3-49bf-b9a9-89581f7e71c5", "95e6539a-09ff-40f0-b944-66e8e27d541d", "8c1f2978-360a-419c-b559-e4bc8c7aaabc", "06185f86-4fc6-4238-aadf-1c5be3061980", "ad7c1dcf-b6d3-4075-b91b-68943f885ad1", "7fa53115-aeec-416f-b3af-db382ed12786", "485a67c7-a2b9-4157-9f6f-a8eccc65c0f8", "90ad95e0-b042-4426-adf6-f376d82cd605", "142d69da-cbb2-4b69-ab82-167a305f29eb"], "befores": [{"name": "driver", "status": "passed", "start": 1716618885589, "stop": 1716618891624}], "afters": [{"name": "driver::0", "status": "broken", "statusDetails": {"message": "OSError: [Errno 22] Invalid argument\n", "trace": "  File \"D:\\sw_install\\python-install\\lib\\site-packages\\allure_commons\\_allure.py\", line 221, in __call__\n    return self._fixture_function(*args, **kwargs)\n  File \"D:\\sw_install\\python-install\\lib\\site-packages\\_pytest\\fixtures.py\", line 918, in _teardown_yield_fixture\n    next(it)\n  File \"D:\\ui\\conftest.py\", line 36, in driver\n    api_clear_data()\n  File \"D:\\ui\\data_clean.py\", line 91, in api_clear_data\n    traceback.print_exc()\n  File \"D:\\sw_install\\python-install\\lib\\traceback.py\", line 179, in print_exc\n    print_exception(*sys.exc_info(), limit=limit, file=file, chain=chain)\n  File \"D:\\sw_install\\python-install\\lib\\traceback.py\", line 121, in print_exception\n    print(line, file=file, end=\"\")\n"}, "start": 1716633923515, "stop": 1716633923618}], "start": 1716618885589, "stop": 1716633923618}